[{
  "history_id" : "pt3n16rz8k0",
  "history_input" : "\n\n\n# Suppress warnings\nimport warnings\nwarnings.simplefilter('ignore')\nwarnings.filterwarnings('ignore')\n\n# Direct access\nimport earthaccess \nfrom pprint import pprint\nimport xarray as xr\n\n# Harmony\nimport geopandas as gpd\nfrom harmony import BBox, Client, Collection, Request, LinkType\nimport datetime as dt\nimport s3fs",
  "history_output" : "",
  "history_begin_time" : 1686794166403,
  "history_end_time" : 1686794169036,
  "history_notes" : null,
  "history_process" : "wttkvt",
  "host_id" : "100001",
  "indicator" : "Done"
},{
  "history_id" : "x4c9nmmo87i",
  "history_input" : "import os\nimport requests\nfrom search_data import *\nfrom harmony import BBox, Client, Collection, Request, LinkType\nimport datetime as dt\nimport s3fs\nimport matplotlib.pyplot as plt\nfrom earth_access_authenticate import *\nimport earthaccess \nfrom pprint import pprint\nimport xarray as xr\n\n# Harmony\nimport geopandas as gpd\n\nssh_short_name = \"SEA_SURFACE_HEIGHT_ALT_GRIDS_L4_2SATS_5DAY_6THDEG_V_JPL2205\"\n\nresults = earthaccess.search_data(\n    short_name=ssh_short_name,\n    cloud_hosted=True,\n    temporal=(\"2021-07-01\", \"2021-09-30\"),\n)\nsst_short_name=\"MUR-JPL-L4-GLOB-v4.1\"\n\nresults = earthaccess.search_data(\n    short_name=ssh_short_name,\n    cloud_hosted=True,\n    temporal=(\"2021-07-01\", \"2021-09-30\"),\n)\n\nauth = earthaccess.login(strategy=\"netrc\", persist=True)\nds = xr.open_mfdataset(earthaccess.open(results))\ngeojson_url = 'https://raw.githubusercontent.com/earth-artificial-intelligence/earth_data_cloud_clinic_geoweaver/main/gulf.json'\n\nhome_dir = os.path.expanduser('~')\ngeojson_path = os.path.join(home_dir, 'gulf.json')\nresponse = requests.get(geojson_url)\nwith open(geojson_path, 'w') as f:\n\tf.write(response.text)\n\ngdf = gpd.read_file(geojson_path) #Return a GeoDataFrame object\n\n\nharmony_client = Client()\nsst_short_name=\"MUR-JPL-L4-GLOB-v4.1\"\n\nrequest = Request(\n  collection=Collection(id=sst_short_name),\n  shape=geojson_path,\n  temporal={\n    'start': dt.datetime(2021, 8, 1, 1),\n    'stop': dt.datetime(2021, 8, 1, 2)   \n  },\n)\njob_id = harmony_client.submit(request)\nharmony_client.wait_for_processing(job_id, show_progress=False)\ndata = harmony_client.result_json(job_id)\nresults = harmony_client.result_urls(job_id, link_type=LinkType.s3)\nurls = list(results)\nurl = urls[0]\n\n",
  "history_output" : "Granules found: 18\nGranules found: 18\nGranules found: 18\nYou're now authenticated with NASA Earthdata Login\nUsing token with expiration date: 07/30/2023\nUsing .netrc file for EDL\n Opening 18 granules, approx size: 0.0 GB\nQUEUEING TASKS | :   0%|          | 0/18 [00:00<?, ?it/s]\nQUEUEING TASKS | : 100%|██████████| 18/18 [00:00<00:00, 3081.78it/s]\nPROCESSING TASKS | :   0%|          | 0/18 [00:00<?, ?it/s]\nPROCESSING TASKS | :   6%|▌         | 1/18 [00:01<00:18,  1.08s/it]\nPROCESSING TASKS | :  33%|███▎      | 6/18 [00:01<00:01,  6.55it/s]\nPROCESSING TASKS | :  50%|█████     | 9/18 [00:01<00:01,  5.55it/s]\nPROCESSING TASKS | :  72%|███████▏  | 13/18 [00:01<00:00,  9.00it/s]\nPROCESSING TASKS | :  89%|████████▉ | 16/18 [00:02<00:00, 10.65it/s]\nPROCESSING TASKS | : 100%|██████████| 18/18 [00:02<00:00,  6.86it/s]\nCOLLECTING RESULTS | :   0%|          | 0/18 [00:00<?, ?it/s]\nCOLLECTING RESULTS | : 100%|██████████| 18/18 [00:00<00:00, 79976.14it/s]\nGranules found: 18\nGranules found: 18\nWe are already authenticated with NASA EDL\n Opening 18 granules, approx size: 0.0 GB\nQUEUEING TASKS | :   0%|          | 0/18 [00:00<?, ?it/s]\nQUEUEING TASKS | : 100%|██████████| 18/18 [00:00<00:00, 1941.76it/s]\nPROCESSING TASKS | :   0%|          | 0/18 [00:00<?, ?it/s]\nPROCESSING TASKS | :   6%|▌         | 1/18 [00:00<00:13,  1.23it/s]\nPROCESSING TASKS | :  33%|███▎      | 6/18 [00:01<00:01,  6.32it/s]\nPROCESSING TASKS | :  44%|████▍     | 8/18 [00:01<00:01,  7.45it/s]\nPROCESSING TASKS | :  56%|█████▌    | 10/18 [00:01<00:00,  8.80it/s]\nPROCESSING TASKS | :  67%|██████▋   | 12/18 [00:01<00:00,  9.56it/s]\nPROCESSING TASKS | :  78%|███████▊  | 14/18 [00:01<00:00,  9.40it/s]\nPROCESSING TASKS | :  94%|█████████▍| 17/18 [00:02<00:00, 10.97it/s]\nPROCESSING TASKS | : 100%|██████████| 18/18 [00:02<00:00,  8.04it/s]\nCOLLECTING RESULTS | :   0%|          | 0/18 [00:00<?, ?it/s]\nCOLLECTING RESULTS | : 100%|██████████| 18/18 [00:00<00:00, 52465.23it/s]\nException ignored in: <function CachingFileManager.__del__ at 0x7fb97d230b80>\nTraceback (most recent call last):\n  File \"/Users/l21-n02609-comm/opt/anaconda3/lib/python3.9/site-packages/xarray/backends/file_manager.py\", line 244, in __del__\n  File \"/Users/l21-n02609-comm/opt/anaconda3/lib/python3.9/site-packages/xarray/backends/file_manager.py\", line 222, in close\n  File \"/Users/l21-n02609-comm/opt/anaconda3/lib/python3.9/site-packages/h5netcdf/core.py\", line 1200, in close\n  File \"/Users/l21-n02609-comm/opt/anaconda3/lib/python3.9/site-packages/h5py/_hl/files.py\", line 463, in close\nTypeError: bad operand type for unary ~: 'NoneType'\nException ignored in: <function File.close at 0x7fb97d88a700>\nTraceback (most recent call last):\n  File \"/Users/l21-n02609-comm/opt/anaconda3/lib/python3.9/site-packages/h5netcdf/core.py\", line 1200, in close\n  File \"/Users/l21-n02609-comm/opt/anaconda3/lib/python3.9/site-packages/h5py/_hl/files.py\", line 463, in close\nTypeError: bad operand type for unary ~: 'NoneType'\nException ignored in: <function CachingFileManager.__del__ at 0x7fb97d230b80>\nTraceback (most recent call last):\n  File \"/Users/l21-n02609-comm/opt/anaconda3/lib/python3.9/site-packages/xarray/backends/file_manager.py\", line 244, in __del__\n  File \"/Users/l21-n02609-comm/opt/anaconda3/lib/python3.9/site-packages/xarray/backends/file_manager.py\", line 222, in close\n  File \"/Users/l21-n02609-comm/opt/anaconda3/lib/python3.9/site-packages/h5netcdf/core.py\", line 1200, in close\n  File \"/Users/l21-n02609-comm/opt/anaconda3/lib/python3.9/site-packages/h5py/_hl/files.py\", line 463, in close\nTypeError: bad operand type for unary ~: 'NoneType'\nException ignored in: <function File.close at 0x7fb97d88a700>\nTraceback (most recent call last):\n  File \"/Users/l21-n02609-comm/opt/anaconda3/lib/python3.9/site-packages/h5netcdf/core.py\", line 1200, in close\n  File \"/Users/l21-n02609-comm/opt/anaconda3/lib/python3.9/site-packages/h5py/_hl/files.py\", line 463, in close\nTypeError: bad operand type for unary ~: 'NoneType'\nException ignored in: <function CachingFileManager.__del__ at 0x7fb97d230b80>\nTraceback (most recent call last):\n  File \"/Users/l21-n02609-comm/opt/anaconda3/lib/python3.9/site-packages/xarray/backends/file_manager.py\", line 244, in __del__\n  File \"/Users/l21-n02609-comm/opt/anaconda3/lib/python3.9/site-packages/xarray/backends/file_manager.py\", line 222, in close\n  File \"/Users/l21-n02609-comm/opt/anaconda3/lib/python3.9/site-packages/h5netcdf/core.py\", line 1200, in close\n  File \"/Users/l21-n02609-comm/opt/anaconda3/lib/python3.9/site-packages/h5py/_hl/files.py\", line 463, in close\nTypeError: bad operand type for unary ~: 'NoneType'\nException ignored in: <function File.close at 0x7fb97d88a700>\nTraceback (most recent call last):\n  File \"/Users/l21-n02609-comm/opt/anaconda3/lib/python3.9/site-packages/h5netcdf/core.py\", line 1200, in close\n  File \"/Users/l21-n02609-comm/opt/anaconda3/lib/python3.9/site-packages/h5py/_hl/files.py\", line 463, in close\nTypeError: bad operand type for unary ~: 'NoneType'\nException ignored in: <function CachingFileManager.__del__ at 0x7fb97d230b80>\nTraceback (most recent call last):\n  File \"/Users/l21-n02609-comm/opt/anaconda3/lib/python3.9/site-packages/xarray/backends/file_manager.py\", line 244, in __del__\n  File \"/Users/l21-n02609-comm/opt/anaconda3/lib/python3.9/site-packages/xarray/backends/file_manager.py\", line 222, in close\n  File \"/Users/l21-n02609-comm/opt/anaconda3/lib/python3.9/site-packages/h5netcdf/core.py\", line 1200, in close\n  File \"/Users/l21-n02609-comm/opt/anaconda3/lib/python3.9/site-packages/h5py/_hl/files.py\", line 463, in close\nTypeError: bad operand type for unary ~: 'NoneType'\nException ignored in: <function File.close at 0x7fb97d88a700>\nTraceback (most recent call last):\n  File \"/Users/l21-n02609-comm/opt/anaconda3/lib/python3.9/site-packages/h5netcdf/core.py\", line 1200, in close\n  File \"/Users/l21-n02609-comm/opt/anaconda3/lib/python3.9/site-packages/h5py/_hl/files.py\", line 463, in close\nTypeError: bad operand type for unary ~: 'NoneType'\nException ignored in: <function CachingFileManager.__del__ at 0x7fb97d230b80>\nTraceback (most recent call last):\n  File \"/Users/l21-n02609-comm/opt/anaconda3/lib/python3.9/site-packages/xarray/backends/file_manager.py\", line 244, in __del__\n  File \"/Users/l21-n02609-comm/opt/anaconda3/lib/python3.9/site-packages/xarray/backends/file_manager.py\", line 222, in close\n  File \"/Users/l21-n02609-comm/opt/anaconda3/lib/python3.9/site-packages/h5netcdf/core.py\", line 1200, in close\n  File \"/Users/l21-n02609-comm/opt/anaconda3/lib/python3.9/site-packages/h5py/_hl/files.py\", line 463, in close\nTypeError: bad operand type for unary ~: 'NoneType'\nException ignored in: <function File.close at 0x7fb97d88a700>\nTraceback (most recent call last):\n  File \"/Users/l21-n02609-comm/opt/anaconda3/lib/python3.9/site-packages/h5netcdf/core.py\", line 1200, in close\n  File \"/Users/l21-n02609-comm/opt/anaconda3/lib/python3.9/site-packages/h5py/_hl/files.py\", line 463, in close\nTypeError: bad operand type for unary ~: 'NoneType'\nException ignored in: <function CachingFileManager.__del__ at 0x7fb97d230b80>\nTraceback (most recent call last):\n  File \"/Users/l21-n02609-comm/opt/anaconda3/lib/python3.9/site-packages/xarray/backends/file_manager.py\", line 244, in __del__\n  File \"/Users/l21-n02609-comm/opt/anaconda3/lib/python3.9/site-packages/xarray/backends/file_manager.py\", line 222, in close\n  File \"/Users/l21-n02609-comm/opt/anaconda3/lib/python3.9/site-packages/h5netcdf/core.py\", line 1200, in close\n  File \"/Users/l21-n02609-comm/opt/anaconda3/lib/python3.9/site-packages/h5py/_hl/files.py\", line 463, in close\nTypeError: bad operand type for unary ~: 'NoneType'\nException ignored in: <function File.close at 0x7fb97d88a700>\nTraceback (most recent call last):\n  File \"/Users/l21-n02609-comm/opt/anaconda3/lib/python3.9/site-packages/h5netcdf/core.py\", line 1200, in close\n  File \"/Users/l21-n02609-comm/opt/anaconda3/lib/python3.9/site-packages/h5py/_hl/files.py\", line 463, in close\nTypeError: bad operand type for unary ~: 'NoneType'\nException ignored in: <function CachingFileManager.__del__ at 0x7fb97d230b80>\nTraceback (most recent call last):\n  File \"/Users/l21-n02609-comm/opt/anaconda3/lib/python3.9/site-packages/xarray/backends/file_manager.py\", line 244, in __del__\n  File \"/Users/l21-n02609-comm/opt/anaconda3/lib/python3.9/site-packages/xarray/backends/file_manager.py\", line 222, in close\n  File \"/Users/l21-n02609-comm/opt/anaconda3/lib/python3.9/site-packages/h5netcdf/core.py\", line 1200, in close\n  File \"/Users/l21-n02609-comm/opt/anaconda3/lib/python3.9/site-packages/h5py/_hl/files.py\", line 463, in close\nTypeError: bad operand type for unary ~: 'NoneType'\nException ignored in: <function File.close at 0x7fb97d88a700>\nTraceback (most recent call last):\n  File \"/Users/l21-n02609-comm/opt/anaconda3/lib/python3.9/site-packages/h5netcdf/core.py\", line 1200, in close\n  File \"/Users/l21-n02609-comm/opt/anaconda3/lib/python3.9/site-packages/h5py/_hl/files.py\", line 463, in close\nTypeError: bad operand type for unary ~: 'NoneType'\nException ignored in: <function CachingFileManager.__del__ at 0x7fb97d230b80>\nTraceback (most recent call last):\n  File \"/Users/l21-n02609-comm/opt/anaconda3/lib/python3.9/site-packages/xarray/backends/file_manager.py\", line 244, in __del__\n  File \"/Users/l21-n02609-comm/opt/anaconda3/lib/python3.9/site-packages/xarray/backends/file_manager.py\", line 222, in close\n  File \"/Users/l21-n02609-comm/opt/anaconda3/lib/python3.9/site-packages/h5netcdf/core.py\", line 1200, in close\n  File \"/Users/l21-n02609-comm/opt/anaconda3/lib/python3.9/site-packages/h5py/_hl/files.py\", line 463, in close\nTypeError: bad operand type for unary ~: 'NoneType'\nException ignored in: <function File.close at 0x7fb97d88a700>\nTraceback (most recent call last):\n  File \"/Users/l21-n02609-comm/opt/anaconda3/lib/python3.9/site-packages/h5netcdf/core.py\", line 1200, in close\n  File \"/Users/l21-n02609-comm/opt/anaconda3/lib/python3.9/site-packages/h5py/_hl/files.py\", line 463, in close\nTypeError: bad operand type for unary ~: 'NoneType'\nException ignored in: <function CachingFileManager.__del__ at 0x7fb97d230b80>\nTraceback (most recent call last):\n  File \"/Users/l21-n02609-comm/opt/anaconda3/lib/python3.9/site-packages/xarray/backends/file_manager.py\", line 244, in __del__\n  File \"/Users/l21-n02609-comm/opt/anaconda3/lib/python3.9/site-packages/xarray/backends/file_manager.py\", line 222, in close\n  File \"/Users/l21-n02609-comm/opt/anaconda3/lib/python3.9/site-packages/h5netcdf/core.py\", line 1200, in close\n  File \"/Users/l21-n02609-comm/opt/anaconda3/lib/python3.9/site-packages/h5py/_hl/files.py\", line 463, in close\nTypeError: bad operand type for unary ~: 'NoneType'\nException ignored in: <function File.close at 0x7fb97d88a700>\nTraceback (most recent call last):\n  File \"/Users/l21-n02609-comm/opt/anaconda3/lib/python3.9/site-packages/h5netcdf/core.py\", line 1200, in close\n  File \"/Users/l21-n02609-comm/opt/anaconda3/lib/python3.9/site-packages/h5py/_hl/files.py\", line 463, in close\nTypeError: bad operand type for unary ~: 'NoneType'\nException ignored in: <function CachingFileManager.__del__ at 0x7fb97d230b80>\nTraceback (most recent call last):\n  File \"/Users/l21-n02609-comm/opt/anaconda3/lib/python3.9/site-packages/xarray/backends/file_manager.py\", line 244, in __del__\n  File \"/Users/l21-n02609-comm/opt/anaconda3/lib/python3.9/site-packages/xarray/backends/file_manager.py\", line 222, in close\n  File \"/Users/l21-n02609-comm/opt/anaconda3/lib/python3.9/site-packages/h5netcdf/core.py\", line 1200, in close\n  File \"/Users/l21-n02609-comm/opt/anaconda3/lib/python3.9/site-packages/h5py/_hl/files.py\", line 463, in close\nTypeError: bad operand type for unary ~: 'NoneType'\nException ignored in: <function File.close at 0x7fb97d88a700>\nTraceback (most recent call last):\n  File \"/Users/l21-n02609-comm/opt/anaconda3/lib/python3.9/site-packages/h5netcdf/core.py\", line 1200, in close\n  File \"/Users/l21-n02609-comm/opt/anaconda3/lib/python3.9/site-packages/h5py/_hl/files.py\", line 463, in close\nTypeError: bad operand type for unary ~: 'NoneType'\nException ignored in: <function CachingFileManager.__del__ at 0x7fb97d230b80>\nTraceback (most recent call last):\n  File \"/Users/l21-n02609-comm/opt/anaconda3/lib/python3.9/site-packages/xarray/backends/file_manager.py\", line 244, in __del__\n  File \"/Users/l21-n02609-comm/opt/anaconda3/lib/python3.9/site-packages/xarray/backends/file_manager.py\", line 222, in close\n  File \"/Users/l21-n02609-comm/opt/anaconda3/lib/python3.9/site-packages/h5netcdf/core.py\", line 1200, in close\n  File \"/Users/l21-n02609-comm/opt/anaconda3/lib/python3.9/site-packages/h5py/_hl/files.py\", line 463, in close\nTypeError: bad operand type for unary ~: 'NoneType'\nException ignored in: <function File.close at 0x7fb97d88a700>\nTraceback (most recent call last):\n  File \"/Users/l21-n02609-comm/opt/anaconda3/lib/python3.9/site-packages/h5netcdf/core.py\", line 1200, in close\n  File \"/Users/l21-n02609-comm/opt/anaconda3/lib/python3.9/site-packages/h5py/_hl/files.py\", line 463, in close\nTypeError: bad operand type for unary ~: 'NoneType'\nException ignored in: <function CachingFileManager.__del__ at 0x7fb97d230b80>\nTraceback (most recent call last):\n  File \"/Users/l21-n02609-comm/opt/anaconda3/lib/python3.9/site-packages/xarray/backends/file_manager.py\", line 244, in __del__\n  File \"/Users/l21-n02609-comm/opt/anaconda3/lib/python3.9/site-packages/xarray/backends/file_manager.py\", line 222, in close\n  File \"/Users/l21-n02609-comm/opt/anaconda3/lib/python3.9/site-packages/h5netcdf/core.py\", line 1200, in close\n  File \"/Users/l21-n02609-comm/opt/anaconda3/lib/python3.9/site-packages/h5py/_hl/files.py\", line 463, in close\nTypeError: bad operand type for unary ~: 'NoneType'\nException ignored in: <function File.close at 0x7fb97d88a700>\nTraceback (most recent call last):\n  File \"/Users/l21-n02609-comm/opt/anaconda3/lib/python3.9/site-packages/h5netcdf/core.py\", line 1200, in close\n  File \"/Users/l21-n02609-comm/opt/anaconda3/lib/python3.9/site-packages/h5py/_hl/files.py\", line 463, in close\nTypeError: bad operand type for unary ~: 'NoneType'\nException ignored in: <function CachingFileManager.__del__ at 0x7fb97d230b80>\nTraceback (most recent call last):\n  File \"/Users/l21-n02609-comm/opt/anaconda3/lib/python3.9/site-packages/xarray/backends/file_manager.py\", line 244, in __del__\n  File \"/Users/l21-n02609-comm/opt/anaconda3/lib/python3.9/site-packages/xarray/backends/file_manager.py\", line 222, in close\n  File \"/Users/l21-n02609-comm/opt/anaconda3/lib/python3.9/site-packages/h5netcdf/core.py\", line 1200, in close\n  File \"/Users/l21-n02609-comm/opt/anaconda3/lib/python3.9/site-packages/h5py/_hl/files.py\", line 463, in close\nTypeError: bad operand type for unary ~: 'NoneType'\nException ignored in: <function File.close at 0x7fb97d88a700>\nTraceback (most recent call last):\n  File \"/Users/l21-n02609-comm/opt/anaconda3/lib/python3.9/site-packages/h5netcdf/core.py\", line 1200, in close\n  File \"/Users/l21-n02609-comm/opt/anaconda3/lib/python3.9/site-packages/h5py/_hl/files.py\", line 463, in close\nTypeError: bad operand type for unary ~: 'NoneType'\nException ignored in: <function CachingFileManager.__del__ at 0x7fb97d230b80>\nTraceback (most recent call last):\n  File \"/Users/l21-n02609-comm/opt/anaconda3/lib/python3.9/site-packages/xarray/backends/file_manager.py\", line 244, in __del__\n  File \"/Users/l21-n02609-comm/opt/anaconda3/lib/python3.9/site-packages/xarray/backends/file_manager.py\", line 222, in close\n  File \"/Users/l21-n02609-comm/opt/anaconda3/lib/python3.9/site-packages/h5netcdf/core.py\", line 1200, in close\n  File \"/Users/l21-n02609-comm/opt/anaconda3/lib/python3.9/site-packages/h5py/_hl/files.py\", line 463, in close\nTypeError: bad operand type for unary ~: 'NoneType'\nException ignored in: <function File.close at 0x7fb97d88a700>\nTraceback (most recent call last):\n  File \"/Users/l21-n02609-comm/opt/anaconda3/lib/python3.9/site-packages/h5netcdf/core.py\", line 1200, in close\n  File \"/Users/l21-n02609-comm/opt/anaconda3/lib/python3.9/site-packages/h5py/_hl/files.py\", line 463, in close\nTypeError: bad operand type for unary ~: 'NoneType'\nException ignored in: <function CachingFileManager.__del__ at 0x7fb97d230b80>\nTraceback (most recent call last):\n  File \"/Users/l21-n02609-comm/opt/anaconda3/lib/python3.9/site-packages/xarray/backends/file_manager.py\", line 244, in __del__\n  File \"/Users/l21-n02609-comm/opt/anaconda3/lib/python3.9/site-packages/xarray/backends/file_manager.py\", line 222, in close\n  File \"/Users/l21-n02609-comm/opt/anaconda3/lib/python3.9/site-packages/h5netcdf/core.py\", line 1200, in close\n  File \"/Users/l21-n02609-comm/opt/anaconda3/lib/python3.9/site-packages/h5py/_hl/files.py\", line 463, in close\nTypeError: bad operand type for unary ~: 'NoneType'\nException ignored in: <function File.close at 0x7fb97d88a700>\nTraceback (most recent call last):\n  File \"/Users/l21-n02609-comm/opt/anaconda3/lib/python3.9/site-packages/h5netcdf/core.py\", line 1200, in close\n  File \"/Users/l21-n02609-comm/opt/anaconda3/lib/python3.9/site-packages/h5py/_hl/files.py\", line 463, in close\nTypeError: bad operand type for unary ~: 'NoneType'\nException ignored in: <function CachingFileManager.__del__ at 0x7fb97d230b80>\nTraceback (most recent call last):\n  File \"/Users/l21-n02609-comm/opt/anaconda3/lib/python3.9/site-packages/xarray/backends/file_manager.py\", line 244, in __del__\n  File \"/Users/l21-n02609-comm/opt/anaconda3/lib/python3.9/site-packages/xarray/backends/file_manager.py\", line 222, in close\n  File \"/Users/l21-n02609-comm/opt/anaconda3/lib/python3.9/site-packages/h5netcdf/core.py\", line 1200, in close\n  File \"/Users/l21-n02609-comm/opt/anaconda3/lib/python3.9/site-packages/h5py/_hl/files.py\", line 463, in close\nTypeError: bad operand type for unary ~: 'NoneType'\nException ignored in: <function File.close at 0x7fb97d88a700>\nTraceback (most recent call last):\n  File \"/Users/l21-n02609-comm/opt/anaconda3/lib/python3.9/site-packages/h5netcdf/core.py\", line 1200, in close\n  File \"/Users/l21-n02609-comm/opt/anaconda3/lib/python3.9/site-packages/h5py/_hl/files.py\", line 463, in close\nTypeError: bad operand type for unary ~: 'NoneType'\nException ignored in: <function CachingFileManager.__del__ at 0x7fb97d230b80>\nTraceback (most recent call last):\n  File \"/Users/l21-n02609-comm/opt/anaconda3/lib/python3.9/site-packages/xarray/backends/file_manager.py\", line 244, in __del__\n  File \"/Users/l21-n02609-comm/opt/anaconda3/lib/python3.9/site-packages/xarray/backends/file_manager.py\", line 222, in close\n  File \"/Users/l21-n02609-comm/opt/anaconda3/lib/python3.9/site-packages/h5netcdf/core.py\", line 1200, in close\n  File \"/Users/l21-n02609-comm/opt/anaconda3/lib/python3.9/site-packages/h5py/_hl/files.py\", line 463, in close\nTypeError: bad operand type for unary ~: 'NoneType'\nException ignored in: <function File.close at 0x7fb97d88a700>\nTraceback (most recent call last):\n  File \"/Users/l21-n02609-comm/opt/anaconda3/lib/python3.9/site-packages/h5netcdf/core.py\", line 1200, in close\n  File \"/Users/l21-n02609-comm/opt/anaconda3/lib/python3.9/site-packages/h5py/_hl/files.py\", line 463, in close\nTypeError: bad operand type for unary ~: 'NoneType'\nException ignored in: <function CachingFileManager.__del__ at 0x7fb97d230b80>\nTraceback (most recent call last):\n  File \"/Users/l21-n02609-comm/opt/anaconda3/lib/python3.9/site-packages/xarray/backends/file_manager.py\", line 244, in __del__\n  File \"/Users/l21-n02609-comm/opt/anaconda3/lib/python3.9/site-packages/xarray/backends/file_manager.py\", line 222, in close\n  File \"/Users/l21-n02609-comm/opt/anaconda3/lib/python3.9/site-packages/h5netcdf/core.py\", line 1200, in close\n  File \"/Users/l21-n02609-comm/opt/anaconda3/lib/python3.9/site-packages/h5py/_hl/files.py\", line 463, in close\nTypeError: bad operand type for unary ~: 'NoneType'\nException ignored in: <function File.close at 0x7fb97d88a700>\nTraceback (most recent call last):\n  File \"/Users/l21-n02609-comm/opt/anaconda3/lib/python3.9/site-packages/h5netcdf/core.py\", line 1200, in close\n  File \"/Users/l21-n02609-comm/opt/anaconda3/lib/python3.9/site-packages/h5py/_hl/files.py\", line 463, in close\nTypeError: bad operand type for unary ~: 'NoneType'\n",
  "history_begin_time" : 1686794170781,
  "history_end_time" : 1686794364808,
  "history_notes" : null,
  "history_process" : "cgvhiy",
  "host_id" : "100001",
  "indicator" : "Done"
},{
  "history_id" : "7zuq4jfbzpp",
  "history_input" : "pip install h5netcdf geopandas s3fs dask matplotlib\npip install requests earthaccess xarray \npip install -U harmony-py",
  "history_output" : "Collecting h5netcdf\n  Using cached h5netcdf-1.2.0-py3-none-any.whl (43 kB)\nRequirement already satisfied: geopandas in /Users/l21-n02609-comm/opt/anaconda3/lib/python3.9/site-packages (0.10.2)\nRequirement already satisfied: s3fs in /Users/l21-n02609-comm/opt/anaconda3/lib/python3.9/site-packages (2022.1.0)\nRequirement already satisfied: dask in /Users/l21-n02609-comm/opt/anaconda3/lib/python3.9/site-packages (2021.10.0)\nRequirement already satisfied: matplotlib in /Users/l21-n02609-comm/opt/anaconda3/lib/python3.9/site-packages (3.4.3)\nRequirement already satisfied: h5py in /Users/l21-n02609-comm/opt/anaconda3/lib/python3.9/site-packages (from h5netcdf) (3.2.1)\nRequirement already satisfied: packaging in /Users/l21-n02609-comm/opt/anaconda3/lib/python3.9/site-packages (from h5netcdf) (21.3)\nRequirement already satisfied: fiona>=1.8 in /Users/l21-n02609-comm/opt/anaconda3/lib/python3.9/site-packages (from geopandas) (1.8.20)\nRequirement already satisfied: pyproj>=2.2.0 in /Users/l21-n02609-comm/opt/anaconda3/lib/python3.9/site-packages (from geopandas) (3.3.0)\nRequirement already satisfied: pandas>=0.25.0 in /Users/l21-n02609-comm/opt/anaconda3/lib/python3.9/site-packages (from geopandas) (1.3.4)\nRequirement already satisfied: shapely>=1.6 in /Users/l21-n02609-comm/opt/anaconda3/lib/python3.9/site-packages (from geopandas) (1.8.1.post1)\nRequirement already satisfied: aiohttp<=4 in /Users/l21-n02609-comm/opt/anaconda3/lib/python3.9/site-packages (from s3fs) (3.8.1)\nRequirement already satisfied: fsspec==2022.01.0 in /Users/l21-n02609-comm/opt/anaconda3/lib/python3.9/site-packages (from s3fs) (2022.1.0)\nRequirement already satisfied: aiobotocore~=2.1.0 in /Users/l21-n02609-comm/opt/anaconda3/lib/python3.9/site-packages (from s3fs) (2.1.0)\nRequirement already satisfied: cloudpickle>=1.1.1 in /Users/l21-n02609-comm/opt/anaconda3/lib/python3.9/site-packages (from dask) (2.0.0)\nRequirement already satisfied: partd>=0.3.10 in /Users/l21-n02609-comm/opt/anaconda3/lib/python3.9/site-packages (from dask) (1.2.0)\nRequirement already satisfied: pyyaml in /Users/l21-n02609-comm/opt/anaconda3/lib/python3.9/site-packages (from dask) (6.0)\nRequirement already satisfied: toolz>=0.8.2 in /Users/l21-n02609-comm/opt/anaconda3/lib/python3.9/site-packages (from dask) (0.11.2)\nRequirement already satisfied: pillow>=6.2.0 in /Users/l21-n02609-comm/opt/anaconda3/lib/python3.9/site-packages (from matplotlib) (9.0.1)\nRequirement already satisfied: pyparsing>=2.2.1 in /Users/l21-n02609-comm/opt/anaconda3/lib/python3.9/site-packages (from matplotlib) (3.0.4)\nRequirement already satisfied: python-dateutil>=2.7 in /Users/l21-n02609-comm/opt/anaconda3/lib/python3.9/site-packages (from matplotlib) (2.8.2)\nRequirement already satisfied: cycler>=0.10 in /Users/l21-n02609-comm/opt/anaconda3/lib/python3.9/site-packages (from matplotlib) (0.10.0)\nRequirement already satisfied: kiwisolver>=1.0.1 in /Users/l21-n02609-comm/opt/anaconda3/lib/python3.9/site-packages (from matplotlib) (1.3.2)\nRequirement already satisfied: numpy>=1.16 in /Users/l21-n02609-comm/opt/anaconda3/lib/python3.9/site-packages (from matplotlib) (1.20.3)\nRequirement already satisfied: aioitertools>=0.5.1 in /Users/l21-n02609-comm/opt/anaconda3/lib/python3.9/site-packages (from aiobotocore~=2.1.0->s3fs) (0.8.0)\nRequirement already satisfied: wrapt>=1.10.10 in /Users/l21-n02609-comm/opt/anaconda3/lib/python3.9/site-packages (from aiobotocore~=2.1.0->s3fs) (1.12.1)\nRequirement already satisfied: botocore<1.23.25,>=1.23.24 in /Users/l21-n02609-comm/opt/anaconda3/lib/python3.9/site-packages (from aiobotocore~=2.1.0->s3fs) (1.23.24)\nRequirement already satisfied: yarl<2.0,>=1.0 in /Users/l21-n02609-comm/opt/anaconda3/lib/python3.9/site-packages (from aiohttp<=4->s3fs) (1.7.2)\nRequirement already satisfied: attrs>=17.3.0 in /Users/l21-n02609-comm/opt/anaconda3/lib/python3.9/site-packages (from aiohttp<=4->s3fs) (21.4.0)\nRequirement already satisfied: frozenlist>=1.1.1 in /Users/l21-n02609-comm/opt/anaconda3/lib/python3.9/site-packages (from aiohttp<=4->s3fs) (1.3.0)\nRequirement already satisfied: aiosignal>=1.1.2 in /Users/l21-n02609-comm/opt/anaconda3/lib/python3.9/site-packages (from aiohttp<=4->s3fs) (1.2.0)\nRequirement already satisfied: async-timeout<5.0,>=4.0.0a3 in /Users/l21-n02609-comm/opt/anaconda3/lib/python3.9/site-packages (from aiohttp<=4->s3fs) (4.0.2)\nRequirement already satisfied: charset-normalizer<3.0,>=2.0 in /Users/l21-n02609-comm/opt/anaconda3/lib/python3.9/site-packages (from aiohttp<=4->s3fs) (2.0.10)\nRequirement already satisfied: multidict<7.0,>=4.5 in /Users/l21-n02609-comm/opt/anaconda3/lib/python3.9/site-packages (from aiohttp<=4->s3fs) (6.0.2)\nRequirement already satisfied: jmespath<1.0.0,>=0.7.1 in /Users/l21-n02609-comm/opt/anaconda3/lib/python3.9/site-packages (from botocore<1.23.25,>=1.23.24->aiobotocore~=2.1.0->s3fs) (0.10.0)\nRequirement already satisfied: urllib3<1.27,>=1.25.4 in /Users/l21-n02609-comm/opt/anaconda3/lib/python3.9/site-packages (from botocore<1.23.25,>=1.23.24->aiobotocore~=2.1.0->s3fs) (1.26.8)\nRequirement already satisfied: six in /Users/l21-n02609-comm/opt/anaconda3/lib/python3.9/site-packages (from cycler>=0.10->matplotlib) (1.16.0)\nRequirement already satisfied: click-plugins>=1.0 in /Users/l21-n02609-comm/opt/anaconda3/lib/python3.9/site-packages (from fiona>=1.8->geopandas) (1.1.1)\nRequirement already satisfied: cligj>=0.5 in /Users/l21-n02609-comm/opt/anaconda3/lib/python3.9/site-packages (from fiona>=1.8->geopandas) (0.7.2)\nRequirement already satisfied: certifi in /Users/l21-n02609-comm/opt/anaconda3/lib/python3.9/site-packages (from fiona>=1.8->geopandas) (2021.10.8)\nRequirement already satisfied: click>=4.0 in /Users/l21-n02609-comm/opt/anaconda3/lib/python3.9/site-packages (from fiona>=1.8->geopandas) (8.0.4)\nRequirement already satisfied: munch in /Users/l21-n02609-comm/opt/anaconda3/lib/python3.9/site-packages (from fiona>=1.8->geopandas) (2.5.0)\nRequirement already satisfied: setuptools in /Users/l21-n02609-comm/opt/anaconda3/lib/python3.9/site-packages (from fiona>=1.8->geopandas) (67.6.0)\nRequirement already satisfied: pytz>=2017.3 in /Users/l21-n02609-comm/opt/anaconda3/lib/python3.9/site-packages (from pandas>=0.25.0->geopandas) (2021.3)\nRequirement already satisfied: locket in /Users/l21-n02609-comm/opt/anaconda3/lib/python3.9/site-packages (from partd>=0.3.10->dask) (0.2.1)\nRequirement already satisfied: idna>=2.0 in /Users/l21-n02609-comm/opt/anaconda3/lib/python3.9/site-packages (from yarl<2.0,>=1.0->aiohttp<=4->s3fs) (3.3)\nInstalling collected packages: h5netcdf\nSuccessfully installed h5netcdf-1.2.0\nRequirement already satisfied: requests in /Users/l21-n02609-comm/opt/anaconda3/lib/python3.9/site-packages (2.28.2)\nRequirement already satisfied: earthaccess in /Users/l21-n02609-comm/opt/anaconda3/lib/python3.9/site-packages (0.5.2)\nRequirement already satisfied: xarray in /Users/l21-n02609-comm/opt/anaconda3/lib/python3.9/site-packages (0.20.2)\nRequirement already satisfied: certifi>=2017.4.17 in /Users/l21-n02609-comm/opt/anaconda3/lib/python3.9/site-packages (from requests) (2021.10.8)\nRequirement already satisfied: idna<4,>=2.5 in /Users/l21-n02609-comm/opt/anaconda3/lib/python3.9/site-packages (from requests) (3.3)\nRequirement already satisfied: urllib3<1.27,>=1.21.1 in /Users/l21-n02609-comm/opt/anaconda3/lib/python3.9/site-packages (from requests) (1.26.8)\nRequirement already satisfied: charset-normalizer<4,>=2 in /Users/l21-n02609-comm/opt/anaconda3/lib/python3.9/site-packages (from requests) (2.0.10)\nRequirement already satisfied: fsspec>=2022.1 in /Users/l21-n02609-comm/opt/anaconda3/lib/python3.9/site-packages (from earthaccess) (2022.1.0)\nRequirement already satisfied: multimethod>=1.8 in /Users/l21-n02609-comm/opt/anaconda3/lib/python3.9/site-packages (from earthaccess) (1.8)\nRequirement already satisfied: tinynetrc<2.0.0,>=1.3.1 in /Users/l21-n02609-comm/opt/anaconda3/lib/python3.9/site-packages (from earthaccess) (1.3.1)\nRequirement already satisfied: s3fs<2024,>=2021.11 in /Users/l21-n02609-comm/opt/anaconda3/lib/python3.9/site-packages (from earthaccess) (2022.1.0)\nRequirement already satisfied: pqdm>=0.1 in /Users/l21-n02609-comm/opt/anaconda3/lib/python3.9/site-packages (from earthaccess) (0.2.0)\nRequirement already satisfied: python-cmr>=0.7 in /Users/l21-n02609-comm/opt/anaconda3/lib/python3.9/site-packages (from earthaccess) (0.7.0)\nRequirement already satisfied: pandas>=1.1 in /Users/l21-n02609-comm/opt/anaconda3/lib/python3.9/site-packages (from xarray) (1.3.4)\nRequirement already satisfied: numpy>=1.18 in /Users/l21-n02609-comm/opt/anaconda3/lib/python3.9/site-packages (from xarray) (1.20.3)\nRequirement already satisfied: python-dateutil>=2.7.3 in /Users/l21-n02609-comm/opt/anaconda3/lib/python3.9/site-packages (from pandas>=1.1->xarray) (2.8.2)\nRequirement already satisfied: pytz>=2017.3 in /Users/l21-n02609-comm/opt/anaconda3/lib/python3.9/site-packages (from pandas>=1.1->xarray) (2021.3)\nRequirement already satisfied: bounded-pool-executor in /Users/l21-n02609-comm/opt/anaconda3/lib/python3.9/site-packages (from pqdm>=0.1->earthaccess) (0.0.3)\nRequirement already satisfied: tqdm in /Users/l21-n02609-comm/opt/anaconda3/lib/python3.9/site-packages (from pqdm>=0.1->earthaccess) (4.63.0)\nRequirement already satisfied: typing-extensions in /Users/l21-n02609-comm/opt/anaconda3/lib/python3.9/site-packages (from pqdm>=0.1->earthaccess) (4.1.1)\nRequirement already satisfied: six>=1.5 in /Users/l21-n02609-comm/opt/anaconda3/lib/python3.9/site-packages (from python-dateutil>=2.7.3->pandas>=1.1->xarray) (1.16.0)\nRequirement already satisfied: aiobotocore~=2.1.0 in /Users/l21-n02609-comm/opt/anaconda3/lib/python3.9/site-packages (from s3fs<2024,>=2021.11->earthaccess) (2.1.0)\nRequirement already satisfied: aiohttp<=4 in /Users/l21-n02609-comm/opt/anaconda3/lib/python3.9/site-packages (from s3fs<2024,>=2021.11->earthaccess) (3.8.1)\nRequirement already satisfied: botocore<1.23.25,>=1.23.24 in /Users/l21-n02609-comm/opt/anaconda3/lib/python3.9/site-packages (from aiobotocore~=2.1.0->s3fs<2024,>=2021.11->earthaccess) (1.23.24)\nRequirement already satisfied: wrapt>=1.10.10 in /Users/l21-n02609-comm/opt/anaconda3/lib/python3.9/site-packages (from aiobotocore~=2.1.0->s3fs<2024,>=2021.11->earthaccess) (1.12.1)\nRequirement already satisfied: aioitertools>=0.5.1 in /Users/l21-n02609-comm/opt/anaconda3/lib/python3.9/site-packages (from aiobotocore~=2.1.0->s3fs<2024,>=2021.11->earthaccess) (0.8.0)\nRequirement already satisfied: attrs>=17.3.0 in /Users/l21-n02609-comm/opt/anaconda3/lib/python3.9/site-packages (from aiohttp<=4->s3fs<2024,>=2021.11->earthaccess) (21.4.0)\nRequirement already satisfied: async-timeout<5.0,>=4.0.0a3 in /Users/l21-n02609-comm/opt/anaconda3/lib/python3.9/site-packages (from aiohttp<=4->s3fs<2024,>=2021.11->earthaccess) (4.0.2)\nRequirement already satisfied: multidict<7.0,>=4.5 in /Users/l21-n02609-comm/opt/anaconda3/lib/python3.9/site-packages (from aiohttp<=4->s3fs<2024,>=2021.11->earthaccess) (6.0.2)\nRequirement already satisfied: frozenlist>=1.1.1 in /Users/l21-n02609-comm/opt/anaconda3/lib/python3.9/site-packages (from aiohttp<=4->s3fs<2024,>=2021.11->earthaccess) (1.3.0)\nRequirement already satisfied: yarl<2.0,>=1.0 in /Users/l21-n02609-comm/opt/anaconda3/lib/python3.9/site-packages (from aiohttp<=4->s3fs<2024,>=2021.11->earthaccess) (1.7.2)\nRequirement already satisfied: aiosignal>=1.1.2 in /Users/l21-n02609-comm/opt/anaconda3/lib/python3.9/site-packages (from aiohttp<=4->s3fs<2024,>=2021.11->earthaccess) (1.2.0)\nRequirement already satisfied: jmespath<1.0.0,>=0.7.1 in /Users/l21-n02609-comm/opt/anaconda3/lib/python3.9/site-packages (from botocore<1.23.25,>=1.23.24->aiobotocore~=2.1.0->s3fs<2024,>=2021.11->earthaccess) (0.10.0)\nRequirement already satisfied: harmony-py in /Users/l21-n02609-comm/opt/anaconda3/lib/python3.9/site-packages (0.4.9)\nRequirement already satisfied: python-dateutil~=2.8.2 in /Users/l21-n02609-comm/opt/anaconda3/lib/python3.9/site-packages (from harmony-py) (2.8.2)\nRequirement already satisfied: sphinxcontrib-napoleon~=0.7 in /Users/l21-n02609-comm/opt/anaconda3/lib/python3.9/site-packages (from harmony-py) (0.7)\nRequirement already satisfied: curlify~=2.2.1 in /Users/l21-n02609-comm/opt/anaconda3/lib/python3.9/site-packages (from harmony-py) (2.2.1)\nRequirement already satisfied: progressbar2~=3.55.0 in /Users/l21-n02609-comm/opt/anaconda3/lib/python3.9/site-packages (from harmony-py) (3.55.0)\nRequirement already satisfied: python-dotenv~=0.20.0 in /Users/l21-n02609-comm/opt/anaconda3/lib/python3.9/site-packages (from harmony-py) (0.20.0)\nRequirement already satisfied: requests~=2.28 in /Users/l21-n02609-comm/opt/anaconda3/lib/python3.9/site-packages (from harmony-py) (2.28.2)\nRequirement already satisfied: python-utils>=2.3.0 in /Users/l21-n02609-comm/opt/anaconda3/lib/python3.9/site-packages (from progressbar2~=3.55.0->harmony-py) (3.6.0)\nRequirement already satisfied: six in /Users/l21-n02609-comm/opt/anaconda3/lib/python3.9/site-packages (from progressbar2~=3.55.0->harmony-py) (1.16.0)\nRequirement already satisfied: typing-extensions in /Users/l21-n02609-comm/opt/anaconda3/lib/python3.9/site-packages (from python-utils>=2.3.0->progressbar2~=3.55.0->harmony-py) (4.1.1)\nRequirement already satisfied: certifi>=2017.4.17 in /Users/l21-n02609-comm/opt/anaconda3/lib/python3.9/site-packages (from requests~=2.28->harmony-py) (2021.10.8)\nRequirement already satisfied: idna<4,>=2.5 in /Users/l21-n02609-comm/opt/anaconda3/lib/python3.9/site-packages (from requests~=2.28->harmony-py) (3.3)\nRequirement already satisfied: charset-normalizer<4,>=2 in /Users/l21-n02609-comm/opt/anaconda3/lib/python3.9/site-packages (from requests~=2.28->harmony-py) (2.0.10)\nRequirement already satisfied: urllib3<1.27,>=1.21.1 in /Users/l21-n02609-comm/opt/anaconda3/lib/python3.9/site-packages (from requests~=2.28->harmony-py) (1.26.8)\nRequirement already satisfied: pockets>=0.3 in /Users/l21-n02609-comm/opt/anaconda3/lib/python3.9/site-packages (from sphinxcontrib-napoleon~=0.7->harmony-py) (0.9.1)\n",
  "history_begin_time" : 1686794155871,
  "history_end_time" : 1686794164741,
  "history_notes" : null,
  "history_process" : "2a8mok",
  "host_id" : "100001",
  "indicator" : "Done"
},{
  "history_id" : "njr9dv2u8c2",
  "history_input" : "# Suppress warnings\nimport os\nimport warnings\nwarnings.simplefilter('ignore')\nwarnings.filterwarnings('ignore')\n\n# Direct access\nimport earthaccess \nfrom pprint import pprint\nimport xarray as xr\n\n# Harmony\nimport geopandas as gpd\nfrom harmony import BBox, Client, Collection, Request, LinkType\nimport datetime as dt\nimport s3fs\nimport matplotlib.pyplot as plt\nfrom earth_access_authenticate import *\n\ncreds = harmony_client.aws_credentials()\ns3_fs = s3fs.S3FileSystem(\n  key=creds['aws_access_key_id'],\n  secret=creds['aws_secret_access_key'],\n  token=creds['aws_session_token'],\n  client_kwargs={'region_name':'us-west-2'},\n)\n\nf = s3_fs.open(url, mode='rb')\nds = xr.open_dataset(f)\nds.analysed_sst.plot()\nhome_dir = os.path.expanduser('~')\nplt.savefig(os.path.join(home_dir, 'plot2.png'))",
  "history_output" : "Granules found: 18\nGranules found: 18\nGranules found: 18\nYou're now authenticated with NASA Earthdata Login\nUsing token with expiration date: 07/30/2023\nUsing .netrc file for EDL\n Opening 18 granules, approx size: 0.0 GB\nQUEUEING TASKS | :   0%|          | 0/18 [00:00<?, ?it/s]\nQUEUEING TASKS | : 100%|██████████| 18/18 [00:00<00:00, 4174.36it/s]\nPROCESSING TASKS | :   0%|          | 0/18 [00:00<?, ?it/s]\nPROCESSING TASKS | :   6%|▌         | 1/18 [00:01<00:22,  1.31s/it]\nPROCESSING TASKS | :  39%|███▉      | 7/18 [00:01<00:01,  6.45it/s]\nPROCESSING TASKS | :  56%|█████▌    | 10/18 [00:02<00:01,  5.60it/s]\nPROCESSING TASKS | :  83%|████████▎ | 15/18 [00:02<00:00,  9.77it/s]\nPROCESSING TASKS | : 100%|██████████| 18/18 [00:02<00:00,  6.47it/s]\nCOLLECTING RESULTS | :   0%|          | 0/18 [00:00<?, ?it/s]\nCOLLECTING RESULTS | : 100%|██████████| 18/18 [00:00<00:00, 76959.71it/s]\nTraceback (most recent call last):\n  File \"/Users/l21-n02609-comm/opt/anaconda3/lib/python3.9/site-packages/s3fs/core.py\", line 261, in _call_s3\n    out = await method(**additional_kwargs)\n  File \"/Users/l21-n02609-comm/opt/anaconda3/lib/python3.9/site-packages/aiobotocore/client.py\", line 187, in _make_api_call\n    raise error_class(parsed_response, operation_name)\nbotocore.exceptions.ClientError: An error occurred (403) when calling the HeadObject operation: Forbidden\nThe above exception was the direct cause of the following exception:\nTraceback (most recent call last):\n  File \"/Users/joe/gw-workspace/njr9dv2u8c2/s3_file_storage.py\", line 28, in <module>\n    f = s3_fs.open(url, mode='rb')\n  File \"/Users/l21-n02609-comm/opt/anaconda3/lib/python3.9/site-packages/fsspec/spec.py\", line 1009, in open\n    f = self._open(\n  File \"/Users/l21-n02609-comm/opt/anaconda3/lib/python3.9/site-packages/s3fs/core.py\", line 552, in _open\n    return S3File(\n  File \"/Users/l21-n02609-comm/opt/anaconda3/lib/python3.9/site-packages/s3fs/core.py\", line 1802, in __init__\n    super().__init__(\n  File \"/Users/l21-n02609-comm/opt/anaconda3/lib/python3.9/site-packages/fsspec/spec.py\", line 1351, in __init__\n    self.size = self.details[\"size\"]\n  File \"/Users/l21-n02609-comm/opt/anaconda3/lib/python3.9/site-packages/fsspec/spec.py\", line 1364, in details\n    self._details = self.fs.info(self.path)\n  File \"/Users/l21-n02609-comm/opt/anaconda3/lib/python3.9/site-packages/fsspec/asyn.py\", line 91, in wrapper\n    return sync(self.loop, func, *args, **kwargs)\n  File \"/Users/l21-n02609-comm/opt/anaconda3/lib/python3.9/site-packages/fsspec/asyn.py\", line 71, in sync\n    raise return_result\n  File \"/Users/l21-n02609-comm/opt/anaconda3/lib/python3.9/site-packages/fsspec/asyn.py\", line 25, in _runner\n    result[0] = await coro\n  File \"/Users/l21-n02609-comm/opt/anaconda3/lib/python3.9/site-packages/s3fs/core.py\", line 1029, in _info\n    out = await self._call_s3(\n  File \"/Users/l21-n02609-comm/opt/anaconda3/lib/python3.9/site-packages/s3fs/core.py\", line 281, in _call_s3\n    raise err\nPermissionError: Forbidden\nException ignored in: <function CachingFileManager.__del__ at 0x7f8f6c4fca60>\nTraceback (most recent call last):\n  File \"/Users/l21-n02609-comm/opt/anaconda3/lib/python3.9/site-packages/xarray/backends/file_manager.py\", line 244, in __del__\n  File \"/Users/l21-n02609-comm/opt/anaconda3/lib/python3.9/site-packages/xarray/backends/file_manager.py\", line 222, in close\n  File \"/Users/l21-n02609-comm/opt/anaconda3/lib/python3.9/site-packages/h5netcdf/core.py\", line 1200, in close\n  File \"/Users/l21-n02609-comm/opt/anaconda3/lib/python3.9/site-packages/h5py/_hl/files.py\", line 463, in close\nTypeError: bad operand type for unary ~: 'NoneType'\nException ignored in: <function File.close at 0x7f8f6c58e5e0>\nTraceback (most recent call last):\n  File \"/Users/l21-n02609-comm/opt/anaconda3/lib/python3.9/site-packages/h5netcdf/core.py\", line 1200, in close\n  File \"/Users/l21-n02609-comm/opt/anaconda3/lib/python3.9/site-packages/h5py/_hl/files.py\", line 463, in close\nTypeError: bad operand type for unary ~: 'NoneType'\nException ignored in: <function CachingFileManager.__del__ at 0x7f8f6c4fca60>\nTraceback (most recent call last):\n  File \"/Users/l21-n02609-comm/opt/anaconda3/lib/python3.9/site-packages/xarray/backends/file_manager.py\", line 244, in __del__\n  File \"/Users/l21-n02609-comm/opt/anaconda3/lib/python3.9/site-packages/xarray/backends/file_manager.py\", line 222, in close\n  File \"/Users/l21-n02609-comm/opt/anaconda3/lib/python3.9/site-packages/h5netcdf/core.py\", line 1200, in close\n  File \"/Users/l21-n02609-comm/opt/anaconda3/lib/python3.9/site-packages/h5py/_hl/files.py\", line 463, in close\nTypeError: bad operand type for unary ~: 'NoneType'\nException ignored in: <function File.close at 0x7f8f6c58e5e0>\nTraceback (most recent call last):\n  File \"/Users/l21-n02609-comm/opt/anaconda3/lib/python3.9/site-packages/h5netcdf/core.py\", line 1200, in close\n  File \"/Users/l21-n02609-comm/opt/anaconda3/lib/python3.9/site-packages/h5py/_hl/files.py\", line 463, in close\nTypeError: bad operand type for unary ~: 'NoneType'\nException ignored in: <function CachingFileManager.__del__ at 0x7f8f6c4fca60>\nTraceback (most recent call last):\n  File \"/Users/l21-n02609-comm/opt/anaconda3/lib/python3.9/site-packages/xarray/backends/file_manager.py\", line 244, in __del__\n  File \"/Users/l21-n02609-comm/opt/anaconda3/lib/python3.9/site-packages/xarray/backends/file_manager.py\", line 222, in close\n  File \"/Users/l21-n02609-comm/opt/anaconda3/lib/python3.9/site-packages/h5netcdf/core.py\", line 1200, in close\n  File \"/Users/l21-n02609-comm/opt/anaconda3/lib/python3.9/site-packages/h5py/_hl/files.py\", line 463, in close\nTypeError: bad operand type for unary ~: 'NoneType'\nException ignored in: <function File.close at 0x7f8f6c58e5e0>\nTraceback (most recent call last):\n  File \"/Users/l21-n02609-comm/opt/anaconda3/lib/python3.9/site-packages/h5netcdf/core.py\", line 1200, in close\n  File \"/Users/l21-n02609-comm/opt/anaconda3/lib/python3.9/site-packages/h5py/_hl/files.py\", line 463, in close\nTypeError: bad operand type for unary ~: 'NoneType'\nException ignored in: <function CachingFileManager.__del__ at 0x7f8f6c4fca60>\nTraceback (most recent call last):\n  File \"/Users/l21-n02609-comm/opt/anaconda3/lib/python3.9/site-packages/xarray/backends/file_manager.py\", line 244, in __del__\n  File \"/Users/l21-n02609-comm/opt/anaconda3/lib/python3.9/site-packages/xarray/backends/file_manager.py\", line 222, in close\n  File \"/Users/l21-n02609-comm/opt/anaconda3/lib/python3.9/site-packages/h5netcdf/core.py\", line 1200, in close\n  File \"/Users/l21-n02609-comm/opt/anaconda3/lib/python3.9/site-packages/h5py/_hl/files.py\", line 463, in close\nTypeError: bad operand type for unary ~: 'NoneType'\nException ignored in: <function File.close at 0x7f8f6c58e5e0>\nTraceback (most recent call last):\n  File \"/Users/l21-n02609-comm/opt/anaconda3/lib/python3.9/site-packages/h5netcdf/core.py\", line 1200, in close\n  File \"/Users/l21-n02609-comm/opt/anaconda3/lib/python3.9/site-packages/h5py/_hl/files.py\", line 463, in close\nTypeError: bad operand type for unary ~: 'NoneType'\nException ignored in: <function CachingFileManager.__del__ at 0x7f8f6c4fca60>\nTraceback (most recent call last):\n  File \"/Users/l21-n02609-comm/opt/anaconda3/lib/python3.9/site-packages/xarray/backends/file_manager.py\", line 244, in __del__\n  File \"/Users/l21-n02609-comm/opt/anaconda3/lib/python3.9/site-packages/xarray/backends/file_manager.py\", line 222, in close\n  File \"/Users/l21-n02609-comm/opt/anaconda3/lib/python3.9/site-packages/h5netcdf/core.py\", line 1200, in close\n  File \"/Users/l21-n02609-comm/opt/anaconda3/lib/python3.9/site-packages/h5py/_hl/files.py\", line 463, in close\nTypeError: bad operand type for unary ~: 'NoneType'\nException ignored in: <function File.close at 0x7f8f6c58e5e0>\nTraceback (most recent call last):\n  File \"/Users/l21-n02609-comm/opt/anaconda3/lib/python3.9/site-packages/h5netcdf/core.py\", line 1200, in close\n  File \"/Users/l21-n02609-comm/opt/anaconda3/lib/python3.9/site-packages/h5py/_hl/files.py\", line 463, in close\nTypeError: bad operand type for unary ~: 'NoneType'\nException ignored in: <function CachingFileManager.__del__ at 0x7f8f6c4fca60>\nTraceback (most recent call last):\n  File \"/Users/l21-n02609-comm/opt/anaconda3/lib/python3.9/site-packages/xarray/backends/file_manager.py\", line 244, in __del__\n  File \"/Users/l21-n02609-comm/opt/anaconda3/lib/python3.9/site-packages/xarray/backends/file_manager.py\", line 222, in close\n  File \"/Users/l21-n02609-comm/opt/anaconda3/lib/python3.9/site-packages/h5netcdf/core.py\", line 1200, in close\n  File \"/Users/l21-n02609-comm/opt/anaconda3/lib/python3.9/site-packages/h5py/_hl/files.py\", line 463, in close\nTypeError: bad operand type for unary ~: 'NoneType'\nException ignored in: <function File.close at 0x7f8f6c58e5e0>\nTraceback (most recent call last):\n  File \"/Users/l21-n02609-comm/opt/anaconda3/lib/python3.9/site-packages/h5netcdf/core.py\", line 1200, in close\n  File \"/Users/l21-n02609-comm/opt/anaconda3/lib/python3.9/site-packages/h5py/_hl/files.py\", line 463, in close\nTypeError: bad operand type for unary ~: 'NoneType'\nException ignored in: <function CachingFileManager.__del__ at 0x7f8f6c4fca60>\nTraceback (most recent call last):\n  File \"/Users/l21-n02609-comm/opt/anaconda3/lib/python3.9/site-packages/xarray/backends/file_manager.py\", line 244, in __del__\n  File \"/Users/l21-n02609-comm/opt/anaconda3/lib/python3.9/site-packages/xarray/backends/file_manager.py\", line 222, in close\n  File \"/Users/l21-n02609-comm/opt/anaconda3/lib/python3.9/site-packages/h5netcdf/core.py\", line 1200, in close\n  File \"/Users/l21-n02609-comm/opt/anaconda3/lib/python3.9/site-packages/h5py/_hl/files.py\", line 463, in close\nTypeError: bad operand type for unary ~: 'NoneType'\nException ignored in: <function File.close at 0x7f8f6c58e5e0>\nTraceback (most recent call last):\n  File \"/Users/l21-n02609-comm/opt/anaconda3/lib/python3.9/site-packages/h5netcdf/core.py\", line 1200, in close\n  File \"/Users/l21-n02609-comm/opt/anaconda3/lib/python3.9/site-packages/h5py/_hl/files.py\", line 463, in close\nTypeError: bad operand type for unary ~: 'NoneType'\nException ignored in: <function CachingFileManager.__del__ at 0x7f8f6c4fca60>\nTraceback (most recent call last):\n  File \"/Users/l21-n02609-comm/opt/anaconda3/lib/python3.9/site-packages/xarray/backends/file_manager.py\", line 244, in __del__\n  File \"/Users/l21-n02609-comm/opt/anaconda3/lib/python3.9/site-packages/xarray/backends/file_manager.py\", line 222, in close\n  File \"/Users/l21-n02609-comm/opt/anaconda3/lib/python3.9/site-packages/h5netcdf/core.py\", line 1200, in close\n  File \"/Users/l21-n02609-comm/opt/anaconda3/lib/python3.9/site-packages/h5py/_hl/files.py\", line 463, in close\nTypeError: bad operand type for unary ~: 'NoneType'\nException ignored in: <function File.close at 0x7f8f6c58e5e0>\nTraceback (most recent call last):\n  File \"/Users/l21-n02609-comm/opt/anaconda3/lib/python3.9/site-packages/h5netcdf/core.py\", line 1200, in close\n  File \"/Users/l21-n02609-comm/opt/anaconda3/lib/python3.9/site-packages/h5py/_hl/files.py\", line 463, in close\nTypeError: bad operand type for unary ~: 'NoneType'\nException ignored in: <function CachingFileManager.__del__ at 0x7f8f6c4fca60>\nTraceback (most recent call last):\n  File \"/Users/l21-n02609-comm/opt/anaconda3/lib/python3.9/site-packages/xarray/backends/file_manager.py\", line 244, in __del__\n  File \"/Users/l21-n02609-comm/opt/anaconda3/lib/python3.9/site-packages/xarray/backends/file_manager.py\", line 222, in close\n  File \"/Users/l21-n02609-comm/opt/anaconda3/lib/python3.9/site-packages/h5netcdf/core.py\", line 1200, in close\n  File \"/Users/l21-n02609-comm/opt/anaconda3/lib/python3.9/site-packages/h5py/_hl/files.py\", line 463, in close\nTypeError: bad operand type for unary ~: 'NoneType'\nException ignored in: <function File.close at 0x7f8f6c58e5e0>\nTraceback (most recent call last):\n  File \"/Users/l21-n02609-comm/opt/anaconda3/lib/python3.9/site-packages/h5netcdf/core.py\", line 1200, in close\n  File \"/Users/l21-n02609-comm/opt/anaconda3/lib/python3.9/site-packages/h5py/_hl/files.py\", line 463, in close\nTypeError: bad operand type for unary ~: 'NoneType'\nException ignored in: <function CachingFileManager.__del__ at 0x7f8f6c4fca60>\nTraceback (most recent call last):\n  File \"/Users/l21-n02609-comm/opt/anaconda3/lib/python3.9/site-packages/xarray/backends/file_manager.py\", line 244, in __del__\n  File \"/Users/l21-n02609-comm/opt/anaconda3/lib/python3.9/site-packages/xarray/backends/file_manager.py\", line 222, in close\n  File \"/Users/l21-n02609-comm/opt/anaconda3/lib/python3.9/site-packages/h5netcdf/core.py\", line 1200, in close\n  File \"/Users/l21-n02609-comm/opt/anaconda3/lib/python3.9/site-packages/h5py/_hl/files.py\", line 463, in close\nTypeError: bad operand type for unary ~: 'NoneType'\nException ignored in: <function File.close at 0x7f8f6c58e5e0>\nTraceback (most recent call last):\n  File \"/Users/l21-n02609-comm/opt/anaconda3/lib/python3.9/site-packages/h5netcdf/core.py\", line 1200, in close\n  File \"/Users/l21-n02609-comm/opt/anaconda3/lib/python3.9/site-packages/h5py/_hl/files.py\", line 463, in close\nTypeError: bad operand type for unary ~: 'NoneType'\nException ignored in: <function CachingFileManager.__del__ at 0x7f8f6c4fca60>\nTraceback (most recent call last):\n  File \"/Users/l21-n02609-comm/opt/anaconda3/lib/python3.9/site-packages/xarray/backends/file_manager.py\", line 244, in __del__\n  File \"/Users/l21-n02609-comm/opt/anaconda3/lib/python3.9/site-packages/xarray/backends/file_manager.py\", line 222, in close\n  File \"/Users/l21-n02609-comm/opt/anaconda3/lib/python3.9/site-packages/h5netcdf/core.py\", line 1200, in close\n  File \"/Users/l21-n02609-comm/opt/anaconda3/lib/python3.9/site-packages/h5py/_hl/files.py\", line 463, in close\nTypeError: bad operand type for unary ~: 'NoneType'\nException ignored in: <function File.close at 0x7f8f6c58e5e0>\nTraceback (most recent call last):\n  File \"/Users/l21-n02609-comm/opt/anaconda3/lib/python3.9/site-packages/h5netcdf/core.py\", line 1200, in close\n  File \"/Users/l21-n02609-comm/opt/anaconda3/lib/python3.9/site-packages/h5py/_hl/files.py\", line 463, in close\nTypeError: bad operand type for unary ~: 'NoneType'\nException ignored in: <function CachingFileManager.__del__ at 0x7f8f6c4fca60>\nTraceback (most recent call last):\n  File \"/Users/l21-n02609-comm/opt/anaconda3/lib/python3.9/site-packages/xarray/backends/file_manager.py\", line 244, in __del__\n  File \"/Users/l21-n02609-comm/opt/anaconda3/lib/python3.9/site-packages/xarray/backends/file_manager.py\", line 222, in close\n  File \"/Users/l21-n02609-comm/opt/anaconda3/lib/python3.9/site-packages/h5netcdf/core.py\", line 1200, in close\n  File \"/Users/l21-n02609-comm/opt/anaconda3/lib/python3.9/site-packages/h5py/_hl/files.py\", line 463, in close\nTypeError: bad operand type for unary ~: 'NoneType'\nException ignored in: <function File.close at 0x7f8f6c58e5e0>\nTraceback (most recent call last):\n  File \"/Users/l21-n02609-comm/opt/anaconda3/lib/python3.9/site-packages/h5netcdf/core.py\", line 1200, in close\n  File \"/Users/l21-n02609-comm/opt/anaconda3/lib/python3.9/site-packages/h5py/_hl/files.py\", line 463, in close\nTypeError: bad operand type for unary ~: 'NoneType'\nException ignored in: <function CachingFileManager.__del__ at 0x7f8f6c4fca60>\nTraceback (most recent call last):\n  File \"/Users/l21-n02609-comm/opt/anaconda3/lib/python3.9/site-packages/xarray/backends/file_manager.py\", line 244, in __del__\n  File \"/Users/l21-n02609-comm/opt/anaconda3/lib/python3.9/site-packages/xarray/backends/file_manager.py\", line 222, in close\n  File \"/Users/l21-n02609-comm/opt/anaconda3/lib/python3.9/site-packages/h5netcdf/core.py\", line 1200, in close\n  File \"/Users/l21-n02609-comm/opt/anaconda3/lib/python3.9/site-packages/h5py/_hl/files.py\", line 463, in close\nTypeError: bad operand type for unary ~: 'NoneType'\nException ignored in: <function File.close at 0x7f8f6c58e5e0>\nTraceback (most recent call last):\n  File \"/Users/l21-n02609-comm/opt/anaconda3/lib/python3.9/site-packages/h5netcdf/core.py\", line 1200, in close\n  File \"/Users/l21-n02609-comm/opt/anaconda3/lib/python3.9/site-packages/h5py/_hl/files.py\", line 463, in close\nTypeError: bad operand type for unary ~: 'NoneType'\nException ignored in: <function CachingFileManager.__del__ at 0x7f8f6c4fca60>\nTraceback (most recent call last):\n  File \"/Users/l21-n02609-comm/opt/anaconda3/lib/python3.9/site-packages/xarray/backends/file_manager.py\", line 244, in __del__\n  File \"/Users/l21-n02609-comm/opt/anaconda3/lib/python3.9/site-packages/xarray/backends/file_manager.py\", line 222, in close\n  File \"/Users/l21-n02609-comm/opt/anaconda3/lib/python3.9/site-packages/h5netcdf/core.py\", line 1200, in close\n  File \"/Users/l21-n02609-comm/opt/anaconda3/lib/python3.9/site-packages/h5py/_hl/files.py\", line 463, in close\nTypeError: bad operand type for unary ~: 'NoneType'\nException ignored in: <function File.close at 0x7f8f6c58e5e0>\nTraceback (most recent call last):\n  File \"/Users/l21-n02609-comm/opt/anaconda3/lib/python3.9/site-packages/h5netcdf/core.py\", line 1200, in close\n  File \"/Users/l21-n02609-comm/opt/anaconda3/lib/python3.9/site-packages/h5py/_hl/files.py\", line 463, in close\nTypeError: bad operand type for unary ~: 'NoneType'\nException ignored in: <function CachingFileManager.__del__ at 0x7f8f6c4fca60>\nTraceback (most recent call last):\n  File \"/Users/l21-n02609-comm/opt/anaconda3/lib/python3.9/site-packages/xarray/backends/file_manager.py\", line 244, in __del__\n  File \"/Users/l21-n02609-comm/opt/anaconda3/lib/python3.9/site-packages/xarray/backends/file_manager.py\", line 222, in close\n  File \"/Users/l21-n02609-comm/opt/anaconda3/lib/python3.9/site-packages/h5netcdf/core.py\", line 1200, in close\n  File \"/Users/l21-n02609-comm/opt/anaconda3/lib/python3.9/site-packages/h5py/_hl/files.py\", line 463, in close\nTypeError: bad operand type for unary ~: 'NoneType'\nException ignored in: <function File.close at 0x7f8f6c58e5e0>\nTraceback (most recent call last):\n  File \"/Users/l21-n02609-comm/opt/anaconda3/lib/python3.9/site-packages/h5netcdf/core.py\", line 1200, in close\n  File \"/Users/l21-n02609-comm/opt/anaconda3/lib/python3.9/site-packages/h5py/_hl/files.py\", line 463, in close\nTypeError: bad operand type for unary ~: 'NoneType'\nException ignored in: <function CachingFileManager.__del__ at 0x7f8f6c4fca60>\nTraceback (most recent call last):\n  File \"/Users/l21-n02609-comm/opt/anaconda3/lib/python3.9/site-packages/xarray/backends/file_manager.py\", line 244, in __del__\n  File \"/Users/l21-n02609-comm/opt/anaconda3/lib/python3.9/site-packages/xarray/backends/file_manager.py\", line 222, in close\n  File \"/Users/l21-n02609-comm/opt/anaconda3/lib/python3.9/site-packages/h5netcdf/core.py\", line 1200, in close\n  File \"/Users/l21-n02609-comm/opt/anaconda3/lib/python3.9/site-packages/h5py/_hl/files.py\", line 463, in close\nTypeError: bad operand type for unary ~: 'NoneType'\nException ignored in: <function File.close at 0x7f8f6c58e5e0>\nTraceback (most recent call last):\n  File \"/Users/l21-n02609-comm/opt/anaconda3/lib/python3.9/site-packages/h5netcdf/core.py\", line 1200, in close\n  File \"/Users/l21-n02609-comm/opt/anaconda3/lib/python3.9/site-packages/h5py/_hl/files.py\", line 463, in close\nTypeError: bad operand type for unary ~: 'NoneType'\nException ignored in: <function CachingFileManager.__del__ at 0x7f8f6c4fca60>\nTraceback (most recent call last):\n  File \"/Users/l21-n02609-comm/opt/anaconda3/lib/python3.9/site-packages/xarray/backends/file_manager.py\", line 244, in __del__\n  File \"/Users/l21-n02609-comm/opt/anaconda3/lib/python3.9/site-packages/xarray/backends/file_manager.py\", line 222, in close\n  File \"/Users/l21-n02609-comm/opt/anaconda3/lib/python3.9/site-packages/h5netcdf/core.py\", line 1200, in close\n  File \"/Users/l21-n02609-comm/opt/anaconda3/lib/python3.9/site-packages/h5py/_hl/files.py\", line 463, in close\nTypeError: bad operand type for unary ~: 'NoneType'\nException ignored in: <function File.close at 0x7f8f6c58e5e0>\nTraceback (most recent call last):\n  File \"/Users/l21-n02609-comm/opt/anaconda3/lib/python3.9/site-packages/h5netcdf/core.py\", line 1200, in close\n  File \"/Users/l21-n02609-comm/opt/anaconda3/lib/python3.9/site-packages/h5py/_hl/files.py\", line 463, in close\nTypeError: bad operand type for unary ~: 'NoneType'\nException ignored in: <function CachingFileManager.__del__ at 0x7f8f6c4fca60>\nTraceback (most recent call last):\n  File \"/Users/l21-n02609-comm/opt/anaconda3/lib/python3.9/site-packages/xarray/backends/file_manager.py\", line 244, in __del__\n  File \"/Users/l21-n02609-comm/opt/anaconda3/lib/python3.9/site-packages/xarray/backends/file_manager.py\", line 222, in close\n  File \"/Users/l21-n02609-comm/opt/anaconda3/lib/python3.9/site-packages/h5netcdf/core.py\", line 1200, in close\n  File \"/Users/l21-n02609-comm/opt/anaconda3/lib/python3.9/site-packages/h5py/_hl/files.py\", line 463, in close\nTypeError: bad operand type for unary ~: 'NoneType'\nException ignored in: <function File.close at 0x7f8f6c58e5e0>\nTraceback (most recent call last):\n  File \"/Users/l21-n02609-comm/opt/anaconda3/lib/python3.9/site-packages/h5netcdf/core.py\", line 1200, in close\n  File \"/Users/l21-n02609-comm/opt/anaconda3/lib/python3.9/site-packages/h5py/_hl/files.py\", line 463, in close\nTypeError: bad operand type for unary ~: 'NoneType'\n",
  "history_begin_time" : 1686794366703,
  "history_end_time" : 1686794477395,
  "history_notes" : null,
  "history_process" : "1b4ko0",
  "host_id" : "100001",
  "indicator" : "Failed"
}]
